Traceback (most recent call last):
  File "C:\Users\luukf\AppData\Local\Programs\Python\Python310\lib\site-packages\jupyter_cache\executors\utils.py", line 58, in single_nb_execution
    executenb(
  File "C:\Users\luukf\AppData\Local\Programs\Python\Python310\lib\site-packages\nbclient\client.py", line 1265, in execute
    return NotebookClient(nb=nb, resources=resources, km=km, **kwargs).execute()
  File "C:\Users\luukf\AppData\Local\Programs\Python\Python310\lib\site-packages\jupyter_core\utils\__init__.py", line 166, in wrapped
    return loop.run_until_complete(inner)
  File "C:\Users\luukf\AppData\Local\Programs\Python\Python310\lib\asyncio\base_events.py", line 641, in run_until_complete
    return future.result()
  File "C:\Users\luukf\AppData\Local\Programs\Python\Python310\lib\site-packages\nbclient\client.py", line 703, in async_execute
    await self.async_execute_cell(
  File "C:\Users\luukf\AppData\Local\Programs\Python\Python310\lib\site-packages\nbclient\client.py", line 1021, in async_execute_cell
    await self._check_raise_for_error(cell, cell_index, exec_reply)
  File "C:\Users\luukf\AppData\Local\Programs\Python\Python310\lib\site-packages\nbclient\client.py", line 915, in _check_raise_for_error
    raise CellExecutionError.from_cell_and_msg(cell, exec_reply_content)
nbclient.exceptions.CellExecutionError: An error occurred while executing the following cell:
------------------
from myst_nb import glue
import matplotlib.pyplot as plt

# Visualize the histogram with the intervals
fig, ax = plt.subplots()
ax.hist(means)
for ln in [clo, chi]:
    ax.axvline(ln, ls='--', c='r')
ax.set_title("Bootstrap distribution and 95% CI")

# And a wider figure to show a timeseries
fig2, ax = plt.subplots(figsize=(6, 2))
ax.plot(np.sort(means), lw=3, c='r')
ax.set_axis_off()

glue("boot_fig", fig, display=False)
glue("sorted_means_fig", fig2, display=False)
------------------

[1;31m---------------------------------------------------------------------------[0m
[1;31mNameError[0m                                 Traceback (most recent call last)
Cell [1;32mIn[1], line 6[0m
[0;32m      4[0m [38;5;66;03m# Visualize the histogram with the intervals[39;00m
[0;32m      5[0m fig, ax [38;5;241m=[39m plt[38;5;241m.[39msubplots()
[1;32m----> 6[0m ax[38;5;241m.[39mhist([43mmeans[49m)
[0;32m      7[0m [38;5;28;01mfor[39;00m ln [38;5;129;01min[39;00m [clo, chi]:
[0;32m      8[0m     ax[38;5;241m.[39maxvline(ln, ls[38;5;241m=[39m[38;5;124m'[39m[38;5;124m--[39m[38;5;124m'[39m, c[38;5;241m=[39m[38;5;124m'[39m[38;5;124mr[39m[38;5;124m'[39m)

[1;31mNameError[0m: name 'means' is not defined
NameError: name 'means' is not defined

